Workbook
Name Slicer_城市: #N/A
Name Slicer_城市1: #N/A

Sheet 1，表格设计
C1: 销售送货单 | T1: 现有客户要求制作如下送货单格式，客户需要A4打印出来，请制作
C2: 送货单号：A000001 | E2: 出货仓库：成品仓储 | H2: 开单时间：20XX-06-05
C3: 客 户：某某市某某科技有限公司 | H3: 开单人：张三
C4: 序号 | D4: 货品编码 | E4: 货品名称 | F4: 单位 | G4: 数量 | H4: 单价 | I4: 小计
C5: 1 | D5: ="D00000"&C5 -> D000001 | E5: 某某商品 | F5: 个 | G5: 100 | H5: 10 | I5: 1000
C6: 2 | D6: ="D00000"&C6 -> D000002 | E6: 某某商品 | F6: 个 | G6: 100 | H6: 10 | I6: 1000
C7: 3
C8: 4
C9: 5
C10: 折扣：0.0000% 收款期限：20XX-06-05 | H10: 合计金额： | I10: 2000
C11: 币种：人民币 应收金额：¥2000.00 大写：贰仟元整 付款方式：转账
C12: 联系人： 联系电话：
C13: 送货地址： 货运信息：
C14: 备注：
C15: 以上货物数量规格实收无误，未付款
C16: （收款以红单为据） | H16: 收货单位及经手人：
H17: （签字或盖章）

Sheet 2，成绩单计算
A1: 学号 | B1: 班级 | C1: 语文成绩 | D1: 数学成绩 | E1: 英文成绩（需要英语成绩表匹配过来） | F1: 加权总成绩(三科权重分别为0.5,0.3,0.2) | G1: 是否有高分科目（任意一门大于85） | H1: 是否优秀学生（三科目都大于80分） | I1: 总体排名 | J1: 班级排名
A2: 001 | B2: 1 | C2: =RANDBETWEEN(50,90) -> 79 | D2: =RANDBETWEEN(50,90) -> 63 | E2: 59 | F2: =0.5*C2+0.3*D2+0.2*E2 -> 70.2 | G2: =IF(OR(C2>85,D2>85,E2>85),"是","否") -> 否 | H2: =IF(OR(C2<=80,D2<=80,E2<=80),"否","是") -> 否 | I2: =_xlfn.RANK.EQ(F2,$F$2:$F$69) -> 29 | J2: {=SUMPRODUCT(($B$2:$B$69=B2)*($F$2:$F$69>F2)) + 1} -> 10
A3: 002 | B3: 1 | C3: =RANDBETWEEN(50,90) -> 88 | D3: =RANDBETWEEN(50,90) -> 71 | E3: 68 | F3: =0.5*C3+0.3*D3+0.2*E3 -> 78.9 | G3: =IF(OR(C3>85,D3>85,E3>85),"是","否") -> 是 | H3: =IF(OR(C3<=80,D3<=80,E3<=80),"否","是") -> 否 | I3: =_xlfn.RANK.EQ(F3,$F$2:$F$69) -> 8 | J3: {=SUMPRODUCT(($B$2:$B$69=B3)*($F$2:$F$69>F3)) + 1} -> 3
A4: 003 | B4: 1 | C4: =RANDBETWEEN(50,90) -> 67 | D4: =RANDBETWEEN(50,90) -> 81 | E4: 66 | F4: =0.5*C4+0.3*D4+0.2*E4 -> 71 | G4: =IF(OR(C4>85,D4>85,E4>85),"是","否") -> 否 | H4: =IF(OR(C4<=80,D4<=80,E4<=80),"否","是") -> 否 | I4: =_xlfn.RANK.EQ(F4,$F$2:$F$69) -> 25 | J4: {=SUMPRODUCT(($B$2:$B$69=B4)*($F$2:$F$69>F4)) + 1} -> 8
A5: 004 | B5: 1 | C5: =RANDBETWEEN(50,90) -> 56 | D5: =RANDBETWEEN(50,90) -> 70 | E5: 84 | F5: =0.5*C5+0.3*D5+0.2*E5 -> 65.8 | G5: =IF(OR(C5>85,D5>85,E5>85),"是","否") -> 否 | H5: =IF(OR(C5<=80,D5<=80,E5<=80),"否","是") -> 否 | I5: =_xlfn.RANK.EQ(F5,$F$2:$F$69) -> 43 | J5: {=SUMPRODUCT(($B$2:$B$69=B5)*($F$2:$F$69>F5)) + 1} -> 16
A6: 005 | B6: 1 | C6: =RANDBETWEEN(50,90) -> 59 | D6: =RANDBETWEEN(50,90) -> 77 | E6: 50 | F6: =0.5*C6+0.3*D6+0.2*E6 -> 62.6 | G6: =IF(OR(C6>85,D6>85,E6>85),"是","否") -> 否 | H6: =IF(OR(C6<=80,D6<=80,E6<=80),"否","是") -> 否 | I6: =_xlfn.RANK.EQ(F6,$F$2:$F$69) -> 57 | J6: {=SUMPRODUCT(($B$2:$B$69=B6)*($F$2:$F$69>F6)) + 1} -> 23
A7: 006 | B7: 1 | C7: =RANDBETWEEN(50,90) -> 59 | D7: =RANDBETWEEN(50,90) -> 74 | E7: 65 | F7: =0.5*C7+0.3*D7+0.2*E7 -> 64.7 | G7: =IF(OR(C7>85,D7>85,E7>85),"是","否") -> 否 | H7: =IF(OR(C7<=80,D7<=80,E7<=80),"否","是") -> 否 | I7: =_xlfn.RANK.EQ(F7,$F$2:$F$69) -> 46 | J7: {=SUMPRODUCT(($B$2:$B$69=B7)*($F$2:$F$69>F7)) + 1} -> 19
A8: 007 | B8: 2 | C8: =RANDBETWEEN(50,90) -> 86 | D8: =RANDBETWEEN(50,90) -> 58 | E8: 84 | F8: =0.5*C8+0.3*D8+0.2*E8 -> 77.2 | G8: =IF(OR(C8>85,D8>85,E8>85),"是","否") -> 是 | H8: =IF(OR(C8<=80,D8<=80,E8<=80),"否","是") -> 否 | I8: =_xlfn.RANK.EQ(F8,$F$2:$F$69) -> 13 | J8: {=SUMPRODUCT(($B$2:$B$69=B8)*($F$2:$F$69>F8)) + 1} -> 5
A9: 008 | B9: 2 | C9: =RANDBETWEEN(50,90) -> 80 | D9: =RANDBETWEEN(50,90) -> 52 | E9: 59 | F9: =0.5*C9+0.3*D9+0.2*E9 -> 67.4 | G9: =IF(OR(C9>85,D9>85,E9>85),"是","否") -> 否 | H9: =IF(OR(C9<=80,D9<=80,E9<=80),"否","是") -> 否 | I9: =_xlfn.RANK.EQ(F9,$F$2:$F$69) -> 37 | J9: {=SUMPRODUCT(($B$2:$B$69=B9)*($F$2:$F$69>F9)) + 1} -> 13
A10: 009 | B10: 2 | C10: =RANDBETWEEN(50,90) -> 52 | D10: =RANDBETWEEN(50,90) -> 83 | E10: 68 | F10: =0.5*C10+0.3*D10+0.2*E10 -> 64.5 | G10: =IF(OR(C10>85,D10>85,E10>85),"是","否") -> 否 | H10: =IF(OR(C10<=80,D10<=80,E10<=80),"否","是") -> 否 | I10: =_xlfn.RANK.EQ(F10,$F$2:$F$69) -> 48 | J10: {=SUMPRODUCT(($B$2:$B$69=B10)*($F$2:$F$69>F10)) + 1} -> 18
A11: 010 | B11: 2 | C11: =RANDBETWEEN(50,90) -> 72 | D11: =RANDBETWEEN(50,90) -> 79 | E11: 71 | F11: =0.5*C11+0.3*D11+0.2*E11 -> 73.9 | G11: =IF(OR(C11>85,D11>85,E11>85),"是","否") -> 否 | H11: =IF(OR(C11<=80,D11<=80,E11<=80),"否","是") -> 否 | I11: =_xlfn.RANK.EQ(F11,$F$2:$F$69) -> 21 | J11: {=SUMPRODUCT(($B$2:$B$69=B11)*($F$2:$F$69>F11)) + 1} -> 7
A12: 011 | B12: 2 | C12: =RANDBETWEEN(50,90) -> 61 | D12: =RANDBETWEEN(50,90) -> 57 | E12: 78 | F12: =0.5*C12+0.3*D12+0.2*E12 -> 63.2 | G12: =IF(OR(C12>85,D12>85,E12>85),"是","否") -> 否 | H12: =IF(OR(C12<=80,D12<=80,E12<=80),"否","是") -> 否 | I12: =_xlfn.RANK.EQ(F12,$F$2:$F$69) -> 54 | J12: {=SUMPRODUCT(($B$2:$B$69=B12)*($F$2:$F$69>F12)) + 1} -> 22
A13: 012 | B13: 2 | C13: =RANDBETWEEN(50,90) -> 54 | D13: =RANDBETWEEN(50,90) -> 60 | E13: 71 | F13: =0.5*C13+0.3*D13+0.2*E13 -> 59.2 | G13: =IF(OR(C13>85,D13>85,E13>85),"是","否") -> 否 | H13: =IF(OR(C13<=80,D13<=80,E13<=80),"否","是") -> 否 | I13: =_xlfn.RANK.EQ(F13,$F$2:$F$69) -> 66 | J13: {=SUMPRODUCT(($B$2:$B$69=B13)*($F$2:$F$69>F13)) + 1} -> 28
... A69: 068 | B69: 2 | C69: =RANDBETWEEN(50,90) -> 55 | D69: =RANDBETWEEN(50,90) -> 75 | E69: 52 | F69: =0.5*C69+0.3*D69+0.2*E69 -> 60.4 | G69: =IF(OR(C69>85,D69>85,E69>85),"是","否") -> 否 | H69: =IF(OR(C69<=80,D69<=80,E69<=80),"否","是") -> 否 | I69: =_xlfn.RANK.EQ(F69,$F$2:$F$69) -> 62 | J69: {=SUMPRODUCT(($B$2:$B$69=B69)*($F$2:$F$69>F69)) + 1} -> 26

Sheet 3，数据清洗
A1: 订单ID | B1: 订单日期 | C1: 发货日期 | D1: 细分 | E1: 城市 | F1: 子类别 | G1: 单价 | H1: 数量 | I1: 金额 | J1: 月份 | K1: 地区 | L1: 订单区域（订单ID前面字母） | M1: 产品编码（订单ID中间部分） | N1: 型号编码（订单ID最后面数字）
A2: CN-2763-5102195 | B2: 44219.21 | C2: 44224.737 | D2: 消费者 | E2: 龙泉 | F2: 用品 | G2: =RANDBETWEEN(10,100) -> 90 | H2: 4 | I2: =G2*H2 -> 360 | J2: =MONTH(B2) -> 1 | K2: =VLOOKUP(E2,地区表!$A$2:$C$255,3,FALSE) -> 西南 | L2: {=_xlfn.TEXTSPLIT(A2,"-")} -> CN | M2: 2763 | N2: 5102195
A3: CN-2763-5102195 | B3: 44219.726 | C3: 44224.522 | D3: 消费者 | E3: 龙泉 | F3: 用品 | G3: =RANDBETWEEN(10,100) -> 56 | H3: 2 | I3: =G3*H3 -> 112 | J3: =MONTH(B3) -> 1 | K3: =VLOOKUP(E3,地区表!$A$2:$C$255,3,FALSE) -> 西南 | L3: {=_xlfn.TEXTSPLIT(A3,"-")} -> CN | M3: 2763 | N3: 5102195
A4: CN-2763-5102195 | B4: 44219.167 | C4: 44224.054 | D4: 消费者 | E4: 龙泉 | F4: 设备 | G4: =RANDBETWEEN(10,100) -> 46 | H4: 4 | I4: =G4*H4 -> 184 | J4: =MONTH(B4) -> 1 | K4: =VLOOKUP(E4,地区表!$A$2:$C$255,3,FALSE) -> 西南 | L4: {=_xlfn.TEXTSPLIT(A4,"-")} -> CN | M4: 2763 | N4: 5102195
A5: CN-2763-5102195 | B5: 44219.187 | C5: 44224.436 | D5: 消费者 | E5: 龙泉 | F5: 椅子 | G5: =RANDBETWEEN(10,100) -> 25 | H5: 1 | I5: =G5*H5 -> 25 | J5: =MONTH(B5) -> 1 | K5: =VLOOKUP(E5,地区表!$A$2:$C$255,3,FALSE) -> 西南 | L5: {=_xlfn.TEXTSPLIT(A5,"-")} -> CN | M5: 2763 | N5: 5102195
A6: CN-2763-5102195 | B6: 44219.13 | C6: 44224.585 | D6: 消费者 | E6: 龙泉 | F6: 装订机 | G6: =RANDBETWEEN(10,100) -> 84 | H6: 3 | I6: =G6*H6 -> 252 | J6: =MONTH(B6) -> 1 | K6: =VLOOKUP(E6,地区表!$A$2:$C$255,3,FALSE) -> 西南 | L6: {=_xlfn.TEXTSPLIT(A6,"-")} -> CN | M6: 2763 | N6: 5102195
A7: CN-2763-5102195 | B7: 44219.12 | C7: 44224.073 | D7: 消费者 | E7: 龙泉 | F7: 电话 | G7: =RANDBETWEEN(10,100) -> 25 | H7: 3 | I7: =G7*H7 -> 75 | J7: =MONTH(B7) -> 1 | K7: =VLOOKUP(E7,地区表!$A$2:$C$255,3,FALSE) -> 西南 | L7: {=_xlfn.TEXTSPLIT(A7,"-")} -> CN | M7: 2763 | N7: 5102195
A8: CN-2818-2328434 | B8: 44274.11 | C8: 44274.225 | D8: 小型企业 | E8: 黎城 | F8: 标签 | G8: =RANDBETWEEN(10,100) -> 29 | H8: 2 | I8: =G8*H8 -> 58 | J8: =MONTH(B8) -> 3 | K8: =VLOOKUP(E8,地区表!$A$2:$C$255,3,FALSE) -> 华东 | L8: {=_xlfn.TEXTSPLIT(A8,"-")} -> CN | M8: 2818 | N8: 2328434
A9: US-2773-4292548 | B9: 44229.139 | C9: 44235.898 | D9: 公司 | E9: 黄石 | F9: 书架 | G9: =RANDBETWEEN(10,100) -> 31 | H9: 2 | I9: =G9*H9 -> 62 | J9: =MONTH(B9) -> 2 | K9: =VLOOKUP(E9,地区表!$A$2:$C$255,3,FALSE) -> 中南 | L9: {=_xlfn.TEXTSPLIT(A9,"-")} -> US | M9: 2773 | N9: 4292548
A10: US-3180-3988119 | B10: 44636.631 | C10: 44639.506 | D10: 消费者 | E10: 黄石 | F10: 美术 | G10: =RANDBETWEEN(10,100) -> 28 | H10: 6 | I10: =G10*H10 -> 168 | J10: =MONTH(B10) -> 3 | K10: =VLOOKUP(E10,地区表!$A$2:$C$255,3,FALSE) -> 中南 | L10: {=_xlfn.TEXTSPLIT(A10,"-")} -> US | M10: 3180 | N10: 3988119
A11: US-3180-3988119 | B11: 44636.973 | C11: 44639.107 | D11: 消费者 | E11: 黄石 | F11: 书架 | G11: =RANDBETWEEN(10,100) -> 95 | H11: 4 | I11: =G11*H11 -> 380 | J11: =MONTH(B11) -> 3 | K11: =VLOOKUP(E11,地区表!$A$2:$C$255,3,FALSE) -> 中南 | L11: {=_xlfn.TEXTSPLIT(A11,"-")} -> US | M11: 3180 | N11: 3988119
A12: US-3180-3988119 | B12: 44636.402 | C12: 44639.485 | D12: 消费者 | E12: 黄石 | F12: 复印机 | G12: =RANDBETWEEN(10,100) -> 45 | H12: 13 | I12: =G12*H12 -> 585 | J12: =MONTH(B12) -> 3 | K12: =VLOOKUP(E12,地区表!$A$2:$C$255,3,FALSE) -> 中南 | L12: {=_xlfn.TEXTSPLIT(A12,"-")} -> US | M12: 3180 | N12: 3988119
A13: CN-2970-2075002 | B13: 44426.137 | C13: 44430.841 | D13: 消费者 | E13: 黄山 | F13: 书架 | G13: =RANDBETWEEN(10,100) -> 77 | H13: 3 | I13: =G13*H13 -> 231 | J13: =MONTH(B13) -> 8 | K13: =VLOOKUP(E13,地区表!$A$2:$C$255,3,FALSE) -> 华东 | L13: {=_xlfn.TEXTSPLIT(A13,"-")} -> CN | M13: 2970 | N13: 2075002
... A999: CN-2417-5378913 | B999: 44968.656 | C999: 44970.2 | D999: 小型企业 | E999: 七台河 | F999: 配件 | G999: =RANDBETWEEN(10,100) -> 32 | H999: 4 | I999: =G999*H999 -> 128 | J999: =MONTH(B999) -> 2 | K999: =VLOOKUP(E999,地区表!$A$2:$C$255,3,FALSE) -> 东北 | L999: {=_xlfn.TEXTSPLIT(A999,"-")} -> CN | M999: 2417 | N999: 5378913

Sheet 4，统计
A1: 订单ID | B1: 订单日期 | C1: 发货日期 | D1: 细分 | E1: 城市 | F1: 子类别 | G1: 单价 | H1: 数量 | I1: 金额 | J1: 类别 | K1: 地区 | L1: 1,统计订单表中细分的产品类别销售金额
A2: US-2982-1357144 | B2: 44438.03 | C2: 44440.856 | D2: 公司 | E2: 杭州 | F2: 用品 | G2: =RANDBETWEEN(10,100) -> 11 | H2: 2 | I2: =G2*H2 -> 22 | J2: =VLOOKUP(F2,地区表!$D$2:$E$18,2,FALSE) -> 办公用品 | K2: =VLOOKUP(E2,地区表!$A$2:$C$255,3,FALSE) -> 华东 | L2: 细分 | M2: 办公用品 | N2: 技术 | O2: 家具
A3: CN-3031-1973789 | B3: 44487.675 | C3: 44491.388 | D3: 消费者 | E3: 内江 | F3: 信封 | G3: =RANDBETWEEN(10,100) -> 55 | H3: 2 | I3: =G3*H3 -> 110 | J3: =VLOOKUP(F3,地区表!$D$2:$E$18,2,FALSE) -> 办公用品 | K3: =VLOOKUP(E3,地区表!$A$2:$C$255,3,FALSE) -> 西南 | L3: 公司 | M3: =SUMIFS(I2:I999,D2:D999,L3,J2:J999,M2) -> 46476 | N3: =SUMIFS(I2:I999,D2:D999,L3,J2:J999,N2) -> 13484 | O3: =SUMIFS(I2:I999,D2:D999,L3,J2:J999,O2) -> 14405
A4: CN-3031-1973789 | B4: 44487.43 | C4: 44491.648 | D4: 消费者 | E4: 内江 | F4: 装订机 | G4: =RANDBETWEEN(10,100) -> 25 | H4: 2 | I4: =G4*H4 -> 50 | J4: =VLOOKUP(F4,地区表!$D$2:$E$18,2,FALSE) -> 办公用品 | K4: =VLOOKUP(E4,地区表!$A$2:$C$255,3,FALSE) -> 西南 | L4: 消费者 | M4: =SUMIFS(I2:I999,D2:D999,L4,J2:J999,M2) -> 57778 | N4: =SUMIFS(I2:I999,D2:D999,L4,J2:J999,N2) -> 26197 | O4: =SUMIFS(I2:I999,D2:D999,L4,J2:J999,O2) -> 21694
A5: US-3208-3017568 | B5: 44664.544 | C5: 44668.276 | D5: 公司 | E5: 镇江 | F5: 用品 | G5: =RANDBETWEEN(10,100) -> 40 | H5: 4 | I5: =G5*H5 -> 160 | J5: =VLOOKUP(F5,地区表!$D$2:$E$18,2,FALSE) -> 办公用品 | K5: =VLOOKUP(E5,地区表!$A$2:$C$255,3,FALSE) -> 华东 | L5: 小型企业 | M5: =SUMIFS(I2:I999,D2:D999,L5,J2:J999,M2) -> 17787 | N5: =SUMIFS(I2:I999,D2:D999,L5,J2:J999,N2) -> 6193 | O5: =SUMIFS(I2:I999,D2:D999,L5,J2:J999,O2) -> 5263
A6: CN-2650-2975416 | B6: 45201.239 | C6: 45203.494 | D6: 消费者 | E6: 汕头 | F6: 器具 | G6: =RANDBETWEEN(10,100) -> 48 | H6: 3 | I6: =G6*H6 -> 144 | J6: =VLOOKUP(F6,地区表!$D$2:$E$18,2,FALSE) -> 办公用品 | K6: =VLOOKUP(E6,地区表!$A$2:$C$255,3,FALSE) -> 中南
A7: CN-2434-4497736 | B7: 44985.131 | C7: 44989.781 | D7: 消费者 | E7: 景德镇 | F7: 设备 | G7: =RANDBETWEEN(10,100) -> 45 | H7: 9 | I7: =G7*H7 -> 405 | J7: =VLOOKUP(F7,地区表!$D$2:$E$18,2,FALSE) -> 技术 | K7: =VLOOKUP(E7,地区表!$A$2:$C$255,3,FALSE) -> 华东
A8: CN-2434-4497736 | B8: 44985.538 | C8: 44989.012 | D8: 消费者 | E8: 景德镇 | F8: 装订机 | G8: =RANDBETWEEN(10,100) -> 30 | H8: 2 | I8: =G8*H8 -> 60 | J8: =VLOOKUP(F8,地区表!$D$2:$E$18,2,FALSE) -> 办公用品 | K8: =VLOOKUP(E8,地区表!$A$2:$C$255,3,FALSE) -> 华东 | L8: 2，公式统计
A9: CN-2434-4497736 | B9: 44985.896 | C9: 44989.882 | D9: 消费者 | E9: 景德镇 | F9: 椅子 | G9: =RANDBETWEEN(10,100) -> 34 | H9: 4 | I9: =G9*H9 -> 136 | J9: =VLOOKUP(F9,地区表!$D$2:$E$18,2,FALSE) -> 家具 | K9: =VLOOKUP(E9,地区表!$A$2:$C$255,3,FALSE) -> 华东 | L9: 办公用品的单笔最大金额 | O9: =_xlfn.MAXIFS(I2:I999,J2:J999,J2) -> 1218
A10: CN-2434-4497736 | B10: 44985.016 | C10: 44989.896 | D10: 消费者 | E10: 景德镇 | F10: 纸张 | G10: =RANDBETWEEN(10,100) -> 46 | H10: 5 | I10: =G10*H10 -> 230 | J10: =VLOOKUP(F10,地区表!$D$2:$E$18,2,FALSE) -> 办公用品 | K10: =VLOOKUP(E10,地区表!$A$2:$C$255,3,FALSE) -> 华东 | L10: 家具的单笔最小金额 | O10: =_xlfn.MINIFS(I2:I999,J2:J999,J9) -> 14
A11: CN-2434-4497736 | B11: 44985.574 | C11: 44989.385 | D11: 消费者 | E11: 景德镇 | F11: 系固件 | G11: =RANDBETWEEN(10,100) -> 75 | H11: 2 | I11: =G11*H11 -> 150 | J11: =VLOOKUP(F11,地区表!$D$2:$E$18,2,FALSE) -> 办公用品 | K11: =VLOOKUP(E11,地区表!$A$2:$C$255,3,FALSE) -> 华东
A12: CN-2124-4195213 | B12: 44675.565 | C12: 44677.208 | D12: 小型企业 | E12: 榆林 | F12: 设备 | G12: =RANDBETWEEN(10,100) -> 94 | H12: 2 | I12: =G12*H12 -> 188 | J12: =VLOOKUP(F12,地区表!$D$2:$E$18,2,FALSE) -> 技术 | K12: =VLOOKUP(E12,地区表!$A$2:$C$255,3,FALSE) -> 西北
A13: CN-3017-5801711 | B13: 44473.568 | C13: 44478.209 | D13: 消费者 | E13: 哈尔滨 | F13: 复印机 | G13: =RANDBETWEEN(10,100) -> 49 | H13: 4 | I13: =G13*H13 -> 196 | J13: =VLOOKUP(F13,地区表!$D$2:$E$18,2,FALSE) -> 技术 | K13: =VLOOKUP(E13,地区表!$A$2:$C$255,3,FALSE) -> 东北 | L13: 一行为一笔交易
A14: CN-2290-2752724 | B14: 44841.642 | C14: 44845.604 | D14: 消费者 | E14: 青岛 | F14: 信封 | G14: =RANDBETWEEN(10,100) -> 56 | H14: 3 | I14: =G14*H14 -> 168 | J14: =VLOOKUP(F14,地区表!$D$2:$E$18,2,FALSE) -> 办公用品 | K14: =VLOOKUP(E14,地区表!$A$2:$C$255,3,FALSE) -> 华东 | L14: 3，统计订单表中细分的产品类别订单笔数
A15: CN-2290-2752724 | B15: 44841.216 | C15: 44845.692 | D15: 消费者 | E15: 青岛 | F15: 配件 | G15: =RANDBETWEEN(10,100) -> 23 | H15: 5 | I15: =G15*H15 -> 115 | J15: =VLOOKUP(F15,地区表!$D$2:$E$18,2,FALSE) -> 技术 | K15: =VLOOKUP(E15,地区表!$A$2:$C$255,3,FALSE) -> 华东 | L15: 地区 | M15: 办公用品 | N15: 技术 | O15: 家具
A16: CN-2290-2752724 | B16: 44841.245 | C16: 44845.714 | D16: 消费者 | E16: 青岛 | F16: 电话 | G16: =RANDBETWEEN(10,100) -> 43 | H16: 2 | I16: =G16*H16 -> 86 | J16: =VLOOKUP(F16,地区表!$D$2:$E$18,2,FALSE) -> 技术 | K16: =VLOOKUP(E16,地区表!$A$2:$C$255,3,FALSE) -> 华东 | L16: 华东 | M16: =SUMIFS(I2:I999,K2:K999,L16,J2:J999,M15) -> 43391 | N16: =SUMIFS(I2:I999,K2:K999,L16,J2:J999,N15) -> 13157 | O16: =SUMIFS(I2:I999,K2:K999,L16,J2:J999,O15) -> 12457
A17: US-2825-2511714 | B17: 44281.93 | C17: 44284.944 | D17: 公司 | E17: 徐州 | F17: 器具 | G17: =RANDBETWEEN(10,100) -> 80 | H17: 7 | I17: =G17*H17 -> 560 | J17: =VLOOKUP(F17,地区表!$D$2:$E$18,2,FALSE) -> 办公用品 | K17: =VLOOKUP(E17,地区表!$A$2:$C$255,3,FALSE) -> 华东 | L17: 西南 | M17: =SUMIFS(I2:I999,K2:K999,L17,J2:J999,M15) -> 11230 | N17: =SUMIFS(I2:I999,K2:K999,L17,J2:J999,N15) -> 6564 | O17: =SUMIFS(I2:I999,K2:K999,L17,J2:J999,O15) -> 2753
A18: US-2825-2511714 | B18: 44281.664 | C18: 44284.015 | D18: 公司 | E18: 徐州 | F18: 标签 | G18: =RANDBETWEEN(10,100) -> 33 | H18: 3 | I18: =G18*H18 -> 99 | J18: =VLOOKUP(F18,地区表!$D$2:$E$18,2,FALSE) -> 办公用品 | K18: =VLOOKUP(E18,地区表!$A$2:$C$255,3,FALSE) -> 华东 | L18: 中南 | M18: =SUMIFS(I2:I999,K2:K999,L18,J2:J999,M15) -> 21148 | N18: =SUMIFS(I2:I999,K2:K999,L18,J2:J999,N15) -> 12347 | O18: =SUMIFS(I2:I999,K2:K999,L18,J2:J999,O15) -> 6704
A19: CN-3140-5631342 | B19: 44596.883 | C19: 44598.763 | D19: 消费者 | E19: 上海 | F19: 配件 | G19: =RANDBETWEEN(10,100) -> 45 | H19: 7 | I19: =G19*H19 -> 315 | J19: =VLOOKUP(F19,地区表!$D$2:$E$18,2,FALSE) -> 技术 | K19: =VLOOKUP(E19,地区表!$A$2:$C$255,3,FALSE) -> 华东 | L19: 西北 | M19: =SUMIFS(I2:I999,K2:K999,L19,J2:J999,M15) -> 7057 | N19: =SUMIFS(I2:I999,K2:K999,L19,J2:J999,N15) -> 2852 | O19: =SUMIFS(I2:I999,K2:K999,L19,J2:J999,O15) -> 2226
A20: CN-3140-5631342 | B20: 44596.03 | C20: 44598.23 | D20: 消费者 | E20: 上海 | F20: 用品 | G20: =RANDBETWEEN(10,100) -> 19 | H20: 1 | I20: =G20*H20 -> 19 | J20: =VLOOKUP(F20,地区表!$D$2:$E$18,2,FALSE) -> 办公用品 | K20: =VLOOKUP(E20,地区表!$A$2:$C$255,3,FALSE) -> 华东 | L20: 东北 | M20: =SUMIFS(I2:I999,K2:K999,L20,J2:J999,M15) -> 23329 | N20: =SUMIFS(I2:I999,K2:K999,L20,J2:J999,N15) -> 7033 | O20: =SUMIFS(I2:I999,K2:K999,L20,J2:J999,O15) -> 8860
A21: CN-3140-5631342 | B21: 44597 | C21: 44598.481 | D21: 消费者 | E21: 上海 | F21: 装订机 | G21: =RANDBETWEEN(10,100) -> 35 | H21: 5 | I21: =G21*H21 -> 175 | J21: =VLOOKUP(F21,地区表!$D$2:$E$18,2,FALSE) -> 办公用品 | K21: =VLOOKUP(E21,地区表!$A$2:$C$255,3,FALSE) -> 华东 | L21: 华北 | M21: =SUMIFS(I2:I999,K2:K999,L21,J2:J999,M15) -> 15886 | N21: =SUMIFS(I2:I999,K2:K999,L21,J2:J999,N15) -> 3921 | O21: =SUMIFS(I2:I999,K2:K999,L21,J2:J999,O15) -> 8362
A22: CN-3140-5631342 | B22: 44596.025 | C22: 44598.934 | D22: 消费者 | E22: 上海 | F22: 装订机 | G22: =RANDBETWEEN(10,100) -> 73 | H22: 6 | I22: =G22*H22 -> 438 | J22: =VLOOKUP(F22,地区表!$D$2:$E$18,2,FALSE) -> 办公用品 | K22: =VLOOKUP(E22,地区表!$A$2:$C$255,3,FALSE) -> 华东
A23: CN-3140-5631342 | B23: 44596.217 | C23: 44598.576 | D23: 消费者 | E23: 上海 | F23: 电话 | G23: =RANDBETWEEN(10,100) -> 60 | H23: 7 | I23: =G23*H23 -> 420 | J23: =VLOOKUP(F23,地区表!$D$2:$E$18,2,FALSE) -> 技术 | K23: =VLOOKUP(E23,地区表!$A$2:$C$255,3,FALSE) -> 华东
A24: CN-3140-5631342 | B24: 44596.505 | C24: 44598.285 | D24: 消费者 | E24: 上海 | F24: 复印机 | G24: =RANDBETWEEN(10,100) -> 27 | H24: 3 | I24: =G24*H24 -> 81 | J24: =VLOOKUP(F24,地区表!$D$2:$E$18,2,FALSE) -> 技术 | K24: =VLOOKUP(E24,地区表!$A$2:$C$255,3,FALSE) -> 华东 | L24: 月份 | M24: 销售额数量 | N24: 销售金额 | O24: 2023年月份销售
A25: CN-3140-5631342 | B25: 44596.541 | C25: 44598.721 | D25: 消费者 | E25: 上海 | F25: 用品 | G25: =RANDBETWEEN(10,100) -> 83 | H25: 2 | I25: =G25*H25 -> 166 | J25: =VLOOKUP(F25,地区表!$D$2:$E$18,2,FALSE) -> 办公用品 | K25: =VLOOKUP(E25,地区表!$A$2:$C$255,3,FALSE) -> 华东 | L25: 1 | M25: =SUMIFS($H$2:$H$999,$B$2:$B$999,">=2023/1/1",$B$2:$B$999,"<=2023/1/31") -> 94 | N25: =SUMIFS($I$2:$I$999,$B$2:$B$999,">=2023/1/1",$B$2:$B$999,"<=2023/1/31") -> 5450
A26: US-2657-4150614 | B26: 45208.448 | C26: 45215.043 | D26: 公司 | E26: 温岭 | F26: 书架 | G26: =RANDBETWEEN(10,100) -> 17 | H26: 4 | I26: =G26*H26 -> 68 | J26: =VLOOKUP(F26,地区表!$D$2:$E$18,2,FALSE) -> 家具 | K26: =VLOOKUP(E26,地区表!$A$2:$C$255,3,FALSE) -> 华东 | L26: 2 | M26: =SUMIFS($H$2:$H$999,$B$2:$B$999,">=2023/2/1",$B$2:$B$999,"<=2023/2/28") -> 98 | N26: =SUMIFS($I$2:$I$999,$B$2:$B$999,">=2023/2/1",$B$2:$B$999,"<=2023/2/28") -> 4827
A27: US-2657-4150614 | B27: 45208.19 | C27: 45215.122 | D27: 公司 | E27: 温岭 | F27: 椅子 | G27: =RANDBETWEEN(10,100) -> 11 | H27: 3 | I27: =G27*H27 -> 33 | J27: =VLOOKUP(F27,地区表!$D$2:$E$18,2,FALSE) -> 家具 | K27: =VLOOKUP(E27,地区表!$A$2:$C$255,3,FALSE) -> 华东 | L27: 3 | M27: =SUMIFS($H$2:$H$999,$B$2:$B$999,">=2023/3/1",$B$2:$B$999,"<=2023/3/31") -> 107 | N27: =SUMIFS($I$2:$I$999,$B$2:$B$999,">=2023/3/1",$B$2:$B$999,"<=2023/3/31") -> 5966
A28: US-2657-4150614 | B28: 45208.894 | C28: 45215.249 | D28: 公司 | E28: 温岭 | F28: 系固件 | G28: =RANDBETWEEN(10,100) -> 34 | H28: 5 | I28: =G28*H28 -> 170 | J28: =VLOOKUP(F28,地区表!$D$2:$E$18,2,FALSE) -> 办公用品 | K28: =VLOOKUP(E28,地区表!$A$2:$C$255,3,FALSE) -> 华东 | L28: 4 | M28: =SUMIFS($H$2:$H$999,$B$2:$B$999,">=2023/4/1",$B$2:$B$999,"<=2023/4/30") -> 71 | N28: =SUMIFS($I$2:$I$999,$B$2:$B$999,">=2023/4/1",$B$2:$B$999,"<=2023/4/30") -> 3678
A29: US-2657-4150614 | B29: 45208.546 | C29: 45215.937 | D29: 公司 | E29: 温岭 | F29: 系固件 | G29: =RANDBETWEEN(10,100) -> 79 | H29: 8 | I29: =G29*H29 -> 632 | J29: =VLOOKUP(F29,地区表!$D$2:$E$18,2,FALSE) -> 办公用品 | K29: =VLOOKUP(E29,地区表!$A$2:$C$255,3,FALSE) -> 华东 | L29: 5 | M29: =SUMIFS($H$2:$H$999,$B$2:$B$999,">=2023/5/1",$B$2:$B$999,"<=2023/5/31") -> 52 | N29: =SUMIFS($I$2:$I$999,$B$2:$B$999,">=2023/5/1",$B$2:$B$999,"<=2023/5/31") -> 2771
A30: US-2657-4150614 | B30: 45208.892 | C30: 45215.825 | D30: 公司 | E30: 温岭 | F30: 用品 | G30: =RANDBETWEEN(10,100) -> 62 | H30: 6 | I30: =G30*H30 -> 372 | J30: =VLOOKUP(F30,地区表!$D$2:$E$18,2,FALSE) -> 办公用品 | K30: =VLOOKUP(E30,地区表!$A$2:$C$255,3,FALSE) -> 华东 | L30: 6 | M30: =SUMIFS($H$2:$H$999,$B$2:$B$999,">=2023/6/1",$B$2:$B$999,"<=2023/6/30") -> 105 | N30: =SUMIFS($I$2:$I$999,$B$2:$B$999,">=2023/6/1",$B$2:$B$999,"<=2023/6/30") -> 6615
A31: US-2657-4150614 | B31: 45208.651 | C31: 45215.978 | D31: 公司 | E31: 温岭 | F31: 配件 | G31: =RANDBETWEEN(10,100) -> 48 | H31: 1 | I31: =G31*H31 -> 48 | J31: =VLOOKUP(F31,地区表!$D$2:$E$18,2,FALSE) -> 技术 | K31: =VLOOKUP(E31,地区表!$A$2:$C$255,3,FALSE) -> 华东 | L31: 7 | M31: =SUMIFS($H$2:$H$999,$B$2:$B$999,">=2023/7/1",$B$2:$B$999,"<=2023/7/31") -> 84 | N31: =SUMIFS($I$2:$I$999,$B$2:$B$999,">=2023/7/1",$B$2:$B$999,"<=2023/7/31") -> 4886
A32: US-2657-4150614 | B32: 45208.521 | C32: 45215.724 | D32: 公司 | E32: 温岭 | F32: 用具 | G32: =RANDBETWEEN(10,100) -> 14 | H32: 2 | I32: =G32*H32 -> 28 | J32: =VLOOKUP(F32,地区表!$D$2:$E$18,2,FALSE) -> 家具 | K32: =VLOOKUP(E32,地区表!$A$2:$C$255,3,FALSE) -> 华东 | L32: 8 | M32: =SUMIFS($H$2:$H$999,$B$2:$B$999,">=2023/8/1",$B$2:$B$999,"<=2023/8/31") -> 30 | N32: =SUMIFS($I$2:$I$999,$B$2:$B$999,">=2023/8/1",$B$2:$B$999,"<=2023/8/31") -> 1818
A33: CN-3211-4364300 | B33: 44667.496 | C33: 44670.743 | D33: 消费者 | E33: 上海 | F33: 装订机 | G33: =RANDBETWEEN(10,100) -> 43 | H33: 5 | I33: =G33*H33 -> 215 | J33: =VLOOKUP(F33,地区表!$D$2:$E$18,2,FALSE) -> 办公用品 | K33: =VLOOKUP(E33,地区表!$A$2:$C$255,3,FALSE) -> 华东 | L33: 9 | M33: =SUMIFS($H$2:$H$999,$B$2:$B$999,">=2023/9/1",$B$2:$B$999,"<=2023/9/30") -> 106 | N33: =SUMIFS($I$2:$I$999,$B$2:$B$999,">=2023/9/1",$B$2:$B$999,"<=2023/9/30") -> 6264
A34: CN-3136-3230180 | B34: 44592.64 | C34: 44596.432 | D34: 公司 | E34: 唐山 | F34: 收纳具 | G34: =RANDBETWEEN(10,100) -> 49 | H34: 2 | I34: =G34*H34 -> 98 | J34: =VLOOKUP(F34,地区表!$D$2:$E$18,2,FALSE) -> 办公用品 | K34: =VLOOKUP(E34,地区表!$A$2:$C$255,3,FALSE) -> 华北 | L34: 10 | M34: =SUMIFS($H$2:$H$999,$B$2:$B$999,">=2023/10/1",$B$2:$B$999,"<=2023/10/31") -> 143 | N34: =SUMIFS($I$2:$I$999,$B$2:$B$999,">=2023/10/1",$B$2:$B$999,"<=2023/10/31") -> 7485
A35: CN-3136-3230180 | B35: 44592.226 | C35: 44596.375 | D35: 公司 | E35: 唐山 | F35: 椅子 | G35: =RANDBETWEEN(10,100) -> 59 | H35: 5 | I35: =G35*H35 -> 295 | J35: =VLOOKUP(F35,地区表!$D$2:$E$18,2,FALSE) -> 家具 | K35: =VLOOKUP(E35,地区表!$A$2:$C$255,3,FALSE) -> 华北 | L35: 11 | M35: =SUMIFS($H$2:$H$999,$B$2:$B$999,">=2023/11/1",$B$2:$B$999,"<=2023/11/30") -> 95 | N35: =SUMIFS($I$2:$I$999,$B$2:$B$999,">=2023/11/1",$B$2:$B$999,"<=2023/11/30") -> 5523
A36: US-2822-1966627 | B36: 44278.535 | C36: 44282.304 | D36: 公司 | E36: 宁波 | F36: 书架 | G36: =RANDBETWEEN(10,100) -> 31 | H36: 4 | I36: =G36*H36 -> 124 | J36: =VLOOKUP(F36,地区表!$D$2:$E$18,2,FALSE) -> 家具 | K36: =VLOOKUP(E36,地区表!$A$2:$C$255,3,FALSE) -> 华东 | L36: 12 | M36: =SUMIFS($H$2:$H$999,$B$2:$B$999,">=2023/12/1",$B$2:$B$999,"<=2023/12/31") -> 142 | N36: =SUMIFS($I$2:$I$999,$B$2:$B$999,">=2023/12/1",$B$2:$B$999,"<=2023/12/31") -> 7955
A37: CN-2558-1190387 | B37: 45109.607 | C37: 45110.888 | D37: 消费者 | E37: 上海 | F37: 用具 | G37: =RANDBETWEEN(10,100) -> 34 | H37: 5 | I37: =G37*H37 -> 170 | J37: =VLOOKUP(F37,地区表!$D$2:$E$18,2,FALSE) -> 家具 | K37: =VLOOKUP(E37,地区表!$A$2:$C$255,3,FALSE) -> 华东
A38: CN-2745-3216455 | B38: 44201.552 | C38: 44204.112 | D38: 公司 | E38: 厦门 | F38: 美术 | G38: =RANDBETWEEN(10,100) -> 34 | H38: 1 | I38: =G38*H38 -> 34 | J38: =VLOOKUP(F38,地区表!$D$2:$E$18,2,FALSE) -> 办公用品 | K38: =VLOOKUP(E38,地区表!$A$2:$C$255,3,FALSE) -> 华东
A39: CN-2759-4690757 | B39: 44215.389 | C39: 44219.38 | D39: 消费者 | E39: 宿州 | F39: 纸张 | G39: =RANDBETWEEN(10,100) -> 75 | H39: 6 | I39: =G39*H39 -> 450 | J39: =VLOOKUP(F39,地区表!$D$2:$E$18,2,FALSE) -> 办公用品 | K39: =VLOOKUP(E39,地区表!$A$2:$C$255,3,FALSE) -> 华东
A40: CN-2759-4690757 | B40: 44215.151 | C40: 44219.358 | D40: 消费者 | E40: 宿州 | F40: 收纳具 | G40: =RANDBETWEEN(10,100) -> 29 | H40: 1 | I40: =G40*H40 -> 29 | J40: =VLOOKUP(F40,地区表!$D$2:$E$18,2,FALSE) -> 办公用品 | K40: =VLOOKUP(E40,地区表!$A$2:$C$255,3,FALSE) -> 华东
...

Sheet 5，透视基础应用(图片)
L1: 分别做出如下三张效果图的透视表

Sheet 5，透视基础应用(透视表)
A1: 订单日期 | B1: 求和项:数量
A2: 1月 | B2: 557
A3: 2月 | B3: 408
A4: 3月 | B4: 462
A5: 4月 | B5: 388
A6: 5月 | B6: 217
A7: 6月 | B7: 237
A8: 7月 | B8: 204
A9: 8月 | B9: 115
A10: 9月 | B10: 295
A11: 10月 | B11: 410
A12: 11月 | B12: 171
A13: 12月 | B13: 318
A14: 总计 | B14: 3782
A18: 平均值项：数量 | B18: 细分
A19: 订单日期 | B19: 公司 | C19: 小型企业 | D19: 消费者 | E19: 总计
A20: 1月 | B20: 3.4042553 | C20: 3.9047619 | D20: 3.9375 | E20: 3.7635135
A21: 2月 | B21: 3.4545455 | C21: 4 | D21: 3.44 | E21: 3.4871795
A22: 3月 | B22: 4.4705882 | C22: 4.75 | D22: 3.6440678 | E22: 4.0884956
A23: 4月 | B23: 4.0909091 | C23: 3.3846154 | D23: 3.9285714 | E23: 3.8415842
A24: 5月 | B24: 4.48 | C24: 2.6 | D24: 4 | E24: 4.0943396
A25: 6月 | B25: 3.8095238 | C25: 5.2 | D25: 3.4473684 | E25: 3.703125
A26: 7月 | B26: 4.1724138 | C26: 5 | D26: 3.5789474 | E26: 4
A27: 8月 | B27: 4.1666667 | C27: 2.4 | D27: 3.7857143 | E27: 3.7096774
A28: 9月 | B28: 4.75 | C28: 3.5555556 | D28: 3.2941176 | E28: 3.6875
A29: 10月 | B29: 3.7560976 | C29: 4.2 | D29: 3.6153846 | E29: 3.6936937
A30: 11月 | B30: 3.375 | C30: 6.3333333 | D30: 3.7619048 | E30: 3.9767442
A31: 12月 | B31: 3.28125 | C31: 4.75 | D31: 3.8043478 | E31: 3.6976744
A32: 总计 | B32: 3.8833819 | C32: 4.0655738 | D32: 3.6660413 | E32: 3.7895792
A36: 求和项：数量 | B36: 订单日期
A37: Row Labels | B37: 2021年 | C37: 2022年 | D37: 2023年 | E37: 总计
A38: 公司 | B38: 469 | C38: 429 | D38: 434 | E38: 1332
A39: 小型企业 | B39: 115 | C39: 260 | D39: 121 | E39: 496
A40: 消费者 | B40: 743 | C40: 613 | D40: 598 | E40: 1954
A41: 书架 | B41: 11 | C41: 21 | D41: 22 | E41: 54
A42: 信封 | B42: 54 | C42: 31 | D42: 38 | E42: 123
A43: 器具 | B43: 55 | C43: 16 | D43: 39 | E43: 110
A44: 复印机 | B44: 45 | C44: 24 | D44: 29 | E44: 98
A45: 收纳具 | B45: 49 | C45: 57 | D45: 39 | E45: 145
A46: 标签 | B46: 32 | C46: 41 | D46: 37 | E46: 110
...

Sheet 6，图表
A1: 海达汽车2024年上半年销售情况表 | S1: 左边数据制作出如下图的三个图
B2: 1月 | C2: 2月 | D2: 3月 | E2: 4月 | F2: 5月 | G2: 6月
A3: 销售数量 | B3: 1312 | C3: 925 | D3: 1020 | E3: 2035 | F3: 3200 | G3: 800
A4: 销售均价 | B4: 85000 | C4: 100000 | D4: 93000 | E4: 89000 | F4: 91000 | G4: 94000

Sheet 英语成绩
A1: 学号 | B1: 英文成绩
A2: 001 | B2: 59
A3: 002 | B3: 68
A4: 003 | B4: 66
A5: 004 | B5: 84
A6: 005 | B6: 50
A7: 006 | B7: 65
A8: 007 | B8: 84
A9: 008 | B9: 59
A10: 009 | B10: 68
A11: 010 | B11: 71
A12: 011 | B12: 78
A13: 012 | B13: 71
... A69: 068 | B69: 52

Sheet 地区表
A1: 城市 | B1: 省/自治区 | C1: 地区 | D1: 子类别 | E1: 类别
A2: 哈尔滨 | B2: 黑龙江 | C2: 东北 | D2: 用品 | E2: 办公用品
A3: 肇源 | B3: 黑龙江 | C3: 东北 | D3: 信封 | E3: 办公用品
A4: 蛟河 | B4: 吉林 | C4: 东北 | D4: 装订机 | E4: 办公用品
A5: 沈阳 | B5: 辽宁 | C5: 东北 | D5: 器具 | E5: 办公用品
A6: 叶柏寿 | B6: 辽宁 | C6: 东北 | D6: 设备 | E6: 技术
A7: 七台河 | B7: 黑龙江 | C7: 东北 | D7: 椅子 | E7: 家具
A8: 青冈 | B8: 黑龙江 | C8: 东北 | D8: 纸张 | E8: 办公用品
A9: 密山 | B9: 黑龙江 | C9: 东北 | D9: 系固件 | E9: 办公用品
A10: 鹤岗 | B10: 黑龙江 | C10: 东北 | D10: 复印机 | E10: 技术
A11: 四平 | B11: 吉林 | C11: 东北 | D11: 配件 | E11: 技术
A12: 抚顺 | B12: 辽宁 | C12: 东北 | D12: 电话 | E12: 技术
... A18: 开原 | B18: 辽宁 | C18: 东北 | D18: 桌子 | E18: 家具
A19: 泰康 | B19: 黑龙江 | C19: 东北
A20: 白城 | B20: 吉林 | C20: 东北
A21: 牡丹江 | B21: 黑龙江 | C21: 东北
A22: 凤城 | B22: 辽宁 | C22: 东北
A23: 双阳 | B23: 吉林 | C23: 东北
A24: 铁力 | B24: 黑龙江 | C24: 东北
A25: 佳木斯 | B25: 黑龙江 | C25: 东北
A26: 铁岭 | B26: 辽宁 | C26: 东北
A27: 庄河 | B27: 辽宁 | C27: 东北
A28: 鸡西 | B28: 黑龙江 | C28: 东北
A29: 大庆 | B29: 黑龙江 | C29: 东北
A30: 宜春 | B30: 黑龙江 | C30: 东北
... A255: 仙桃 | B255: 湖北 | C255: 中南

Sheet 透视表数据源
A1: 订单ID | B1: 订单日期 | C1: 发货日期 | D1: 细分 | E1: 城市 | F1: 子类别 | G1: 单价 | H1: 数量
A2: US-2982-1357144 | B2: 44438.03 | C2: 44440.856 | D2: 公司 | E2: 杭州 | F2: 用品 | G2: =RANDBETWEEN(10,100) -> 81 | H2: 2
A3: CN-3031-1973789 | B3: 44487.675 | C3: 44491.388 | D3: 消费者 | E3: 内江 | F3: 信封 | G3: =RANDBETWEEN(10,100) -> 20 | H3: 2
A4: CN-3031-1973789 | B4: 44487.43 | C4: 44491.648 | D4: 消费者 | E4: 内江 | F4: 装订机 | G4: =RANDBETWEEN(10,100) -> 66 | H4: 2
A5: US-3208-3017568 | B5: 44664.544 | C5: 44668.276 | D5: 公司 | E5: 镇江 | F5: 用品 | G5: =RANDBETWEEN(10,100) -> 93 | H5: 4
A6: CN-2650-2975416 | B6: 45201.239 | C6: 45203.494 | D6: 消费者 | E6: 汕头 | F6: 器具 | G6: =RANDBETWEEN(10,100) -> 34 | H6: 3
A7: CN-2434-4497736 | B7: 44985.131 | C7: 44989.781 | D7: 消费者 | E7: 景德镇 | F7: 设备 | G7: =RANDBETWEEN(10,100) -> 98 | H7: 9
A8: CN-2434-4497736 | B8: 44985.538 | C8: 44989.012 | D8: 消费者 | E8: 景德镇 | F8: 装订机 | G8: =RANDBETWEEN(10,100) -> 14 | H8: 2
A9: CN-2434-4497736 | B9: 44985.896 | C9: 44989.882 | D9: 消费者 | E9: 景德镇 | F9: 椅子 | G9: =RANDBETWEEN(10,100) -> 86 | H9: 4
A10: CN-2434-4497736 | B10: 44985.016 | C10: 44989.896 | D10: 消费者 | E10: 景德镇 | F10: 纸张 | G10: =RANDBETWEEN(10,100) -> 85 | H10: 5
A11: CN-2434-4497736 | B11: 44985.574 | C11: 44989.385 | D11: 消费者 | E11: 景德镇 | F11: 系固件 | G11: =RANDBETWEEN(10,100) -> 26 | H11: 2
A12: CN-2124-4195213 | B12: 44675.565 | C12: 44677.208 | D12: 小型企业 | E12: 榆林 | F12: 设备 | G12: =RANDBETWEEN(10,100) -> 41 | H12: 2
A13: CN-3017-5801711 | B13: 44473.568 | C13: 44478.209 | D13: 消费者 | E13: 哈尔滨 | F13: 复印机 | G13: =RANDBETWEEN(10,100) -> 66 | H13: 4
... A999: CN-3146-1512811 | B999: 44602.143 | C999: 44607.632 | D999: 消费者 | E999: 肇庆 | F999: 收纳具 | G999: =RANDBETWEEN(10,100) -> 34 | H999: 3
